2024-05-08 17:30:08,781 INFO    StreamThr :16844 [internal.py:wandb_internal():85] W&B internal server running at pid: 16844, started at: 2024-05-08 17:30:08.781378
2024-05-08 17:30:08,781 DEBUG   HandlerThread:16844 [handler.py:handle_request():158] handle_request: status
2024-05-08 17:30:08,805 INFO    WriterThread:16844 [datastore.py:open_for_write():87] open: d:\Dev\Projects D\Anja\MA\wandb\run-20240508_173008-qfuklnqt\run-qfuklnqt.wandb
2024-05-08 17:30:08,805 DEBUG   SenderThread:16844 [sender.py:send():378] send: header
2024-05-08 17:30:08,844 DEBUG   SenderThread:16844 [sender.py:send():378] send: run
2024-05-08 17:30:08,923 DEBUG   HandlerThread:16844 [handler.py:handle_request():158] handle_request: status_report
2024-05-08 17:30:09,190 ERROR   SenderThread:16844 [internal_api.py:execute():344] 404 response executing GraphQL.
2024-05-08 17:30:09,190 ERROR   SenderThread:16844 [internal_api.py:execute():345] {"errors":[{"message":"entity team-recipe-ingredients not found during upsertBucket","path":["upsertBucket"]}],"data":{"upsertBucket":null}}
2024-05-08 17:30:09,190 ERROR   SenderThread:16844 [sender.py:send_run():970] It appears that you do not have permission to access the requested resource. Please reach out to the project owner to grant you access. If you have the correct permissions, verify that there are no issues with your networking setup.(Error 404: Not Found)
Traceback (most recent call last):
  File "d:\Dev\miniconda\envs\anja-ma\lib\site-packages\wandb\sdk\lib\retry.py", line 131, in __call__
    result = self._call_fn(*args, **kwargs)
  File "d:\Dev\miniconda\envs\anja-ma\lib\site-packages\wandb\sdk\internal\internal_api.py", line 340, in execute
    return self.client.execute(*args, **kwargs)  # type: ignore
  File "d:\Dev\miniconda\envs\anja-ma\lib\site-packages\wandb\vendor\gql-0.2.0\wandb_gql\client.py", line 52, in execute
    result = self._get_result(document, *args, **kwargs)
  File "d:\Dev\miniconda\envs\anja-ma\lib\site-packages\wandb\vendor\gql-0.2.0\wandb_gql\client.py", line 60, in _get_result
    return self.transport.execute(document, *args, **kwargs)
  File "d:\Dev\miniconda\envs\anja-ma\lib\site-packages\wandb\sdk\lib\gql_request.py", line 59, in execute
    request.raise_for_status()
  File "d:\Dev\miniconda\envs\anja-ma\lib\site-packages\requests\models.py", line 1021, in raise_for_status
    raise HTTPError(http_error_msg, response=self)
requests.exceptions.HTTPError: 404 Client Error: Not Found for url: https://api.wandb.ai/graphql

During handling of the above exception, another exception occurred:

Traceback (most recent call last):
  File "d:\Dev\miniconda\envs\anja-ma\lib\site-packages\wandb\sdk\internal\sender.py", line 968, in send_run
    server_run = self._init_run(run, config_value_dict)
  File "d:\Dev\miniconda\envs\anja-ma\lib\site-packages\wandb\sdk\internal\sender.py", line 1013, in _init_run
    server_run, inserted, server_messages = self._api.upsert_run(
  File "d:\Dev\miniconda\envs\anja-ma\lib\site-packages\wandb\apis\normalize.py", line 73, in wrapper
    raise err
  File "d:\Dev\miniconda\envs\anja-ma\lib\site-packages\wandb\apis\normalize.py", line 41, in wrapper
    return func(*args, **kwargs)
  File "d:\Dev\miniconda\envs\anja-ma\lib\site-packages\wandb\sdk\internal\internal_api.py", line 2188, in upsert_run
    response = self.gql(
  File "d:\Dev\miniconda\envs\anja-ma\lib\site-packages\wandb\sdk\internal\internal_api.py", line 312, in gql
    ret = self._retry_gql(
  File "d:\Dev\miniconda\envs\anja-ma\lib\site-packages\wandb\sdk\lib\retry.py", line 147, in __call__
    retry_timedelta_triggered = check_retry_fn(e)
  File "d:\Dev\miniconda\envs\anja-ma\lib\site-packages\wandb\util.py", line 965, in check_retry_fn
    return fallback_retry_fn(e)
  File "d:\Dev\miniconda\envs\anja-ma\lib\site-packages\wandb\util.py", line 907, in no_retry_auth
    raise CommError(
wandb.errors.CommError: It appears that you do not have permission to access the requested resource. Please reach out to the project owner to grant you access. If you have the correct permissions, verify that there are no issues with your networking setup.(Error 404: Not Found)
2024-05-08 17:30:13,903 DEBUG   HandlerThread:16844 [handler.py:handle_request():158] handle_request: keepalive
2024-05-08 17:30:13,951 DEBUG   HandlerThread:16844 [handler.py:handle_request():158] handle_request: status_report
2024-05-08 17:30:14,244 DEBUG   HandlerThread:16844 [handler.py:handle_request():158] handle_request: status_report
2024-05-08 17:30:18,933 DEBUG   HandlerThread:16844 [handler.py:handle_request():158] handle_request: keepalive
2024-05-08 17:30:18,977 DEBUG   HandlerThread:16844 [handler.py:handle_request():158] handle_request: status_report
2024-05-08 17:30:19,275 DEBUG   HandlerThread:16844 [handler.py:handle_request():158] handle_request: status_report
2024-05-08 17:30:23,962 DEBUG   HandlerThread:16844 [handler.py:handle_request():158] handle_request: keepalive
2024-05-08 17:30:24,009 DEBUG   HandlerThread:16844 [handler.py:handle_request():158] handle_request: status_report
2024-05-08 17:30:24,308 DEBUG   HandlerThread:16844 [handler.py:handle_request():158] handle_request: status_report
2024-05-08 17:30:28,993 DEBUG   HandlerThread:16844 [handler.py:handle_request():158] handle_request: keepalive
2024-05-08 17:30:29,040 DEBUG   HandlerThread:16844 [handler.py:handle_request():158] handle_request: status_report
2024-05-08 17:30:29,339 DEBUG   HandlerThread:16844 [handler.py:handle_request():158] handle_request: status_report
2024-05-08 17:30:34,027 DEBUG   HandlerThread:16844 [handler.py:handle_request():158] handle_request: keepalive
2024-05-08 17:30:34,074 DEBUG   HandlerThread:16844 [handler.py:handle_request():158] handle_request: status_report
2024-05-08 17:30:34,373 DEBUG   HandlerThread:16844 [handler.py:handle_request():158] handle_request: status_report
2024-05-08 17:30:39,059 DEBUG   HandlerThread:16844 [handler.py:handle_request():158] handle_request: keepalive
2024-05-08 17:30:39,107 DEBUG   HandlerThread:16844 [handler.py:handle_request():158] handle_request: status_report
2024-05-08 17:30:39,408 DEBUG   HandlerThread:16844 [handler.py:handle_request():158] handle_request: status_report
